Workbook

Sheet JANUARI
R2: DATA KELEMBABAN
R3: Bulan : | T3: ='[1]1'!AA1 -> JANUARI | V3: 2022
A5: JAM | B5: 00.00 | C5: 01.00 | D5: 02.00 | E5: 03.00 | F5: 04.00 | G5: 05.00 | H5: 06.00 | I5: 07.00 | J5: 08.00 | K5: 09.00 | L5: 10.00 | M5: 11.00 | N5: 12.00 | O5: 13.00 | P5: 14.00 | Q5: 15.00 | R5: 16.00 | S5: 17.00 | T5: 18.00 | U5: 19.00 | V5: 20.00 | W5: 21.00 | X5: 22.00 | Y5: 23.00 | Z5: rata2 | AA5: Max | AB5: Min
A6: TGL | B6: 1 | C6: 2 | D6: 3 | E6: 4 | F6: 5 | G6: 6 | H6: 7 | I6: 8 | J6: 9 | K6: 10 | L6: 11 | M6: 12 | N6: 13 | O6: 14 | P6: 15 | Q6: 16 | R6: 17 | S6: 18 | T6: 19 | U6: 20 | V6: 21 | W6: 22 | X6: 23 | Y6: 24 | Z6: 25 | AA6: 26 | AB6: 27
A7: 1 | B7: 82.588198 | C7: 75.775603 | D7: 66.900193 | E7: 66.661614 | F7: 61.320169 | G7: 59.742484 | H7: 67.447127 | I7: 69.004717 | J7: 72.492861 | K7: 73.627426 | L7: 78.650584 | M7: 77.108358 | N7: 79.841062 | Z7: =AVERAGE(B7:N7) -> 71.627723 | AA7: =MAX(B7:N7) -> 82.588198 | AB7: =MIN(B7:Y7) -> 59.742484
A8: 2 | B8: 94.163464 | C8: 81.406521 | D8: 74.790838 | E8: 69.815294 | F8: 69.342913 | G8: 66.42899 | H8: 67.971722 | I8: 68.878309 | J8: 72.378181 | K8: 74.89726 | L8: 75.278017 | M8: 80.624211 | N8: 84.914793 | Z8: =AVERAGE(B8:N8) -> 75.453116 | AA8: =MAX(B8:N8) -> 94.163464 | AB8: =MIN(B8:Y8) -> 66.42899
A9: 3 | B9: 89.252861 | C9: 84.042334 | D9: 74.844084 | E9: 73.98548 | F9: 66.013058 | G9: 63.74275 | H9: 57.790496 | I9: 58.047041 | J9: 60.151797 | K9: 66.900193 | L9: 66.329634 | M9: 73.897493 | N9: 77.876993 | Z9: =AVERAGE(B9:N9) -> 70.221093 | AA9: =MAX(B9:N9) -> 89.252861 | AB9: =MIN(B9:Y9) -> 57.790496
A10: 4 | B10: 80.174452 | C10: 74.128057 | D10: 70.784128 | E10: 69.689179 | F10: 64.376531 | G10: 62.24177 | H10: 66.765845 | I10: 63.261822 | J10: 61.397248 | K10: 65.08409 | L10: 68.958048 | M10: 74.519815 | N10: 79.010509 | Z10: =AVERAGE(B10:N10) -> 69.260884 | AA10: =MAX(B10:N10) -> 80.174452 | AB10: =MIN(B10:Y10) -> 61.397248
A11: 5 | B11: 85.320624 | C11: 73.646627 | D11: 64.477474 | E11: 57.175946 | F11: 56.493445 | G11: 57.362744 | H11: 59.544257 | I11: 57.11332 | J11: 58.548278 | K11: 58.215856 | L11: 65.583842 | M11: 64.125147 | N11: 68.90387 | Z11: =AVERAGE(B11:N11) -> 63.577802 | AA11: =MAX(B11:N11) -> 85.320624 | AB11: =MIN(B11:Y11) -> 56.493445
A12: 6 | B12: 83.672295 | C12: 73.296724 | D12: 62.501844 | E12: 60.744979 | F12: 58.047041 | G12: 60.058413 | H12: 58.36647 | I12: 58.382927 | J12: 60.313839 | K12: 61.230544 | L12: 66.900193 | M12: 68.091531 | N12: 69.171221 | Z12: =AVERAGE(B12:N12) -> 64.675232 | AA12: =MAX(B12:N12) -> 83.672295 | AB12: =MIN(B12:Y12) -> 58.047041
A13: 7 | B13: 82.509603 | C13: 71.540676 | D13: 65.871489 | E13: 62.635286 | F13: 62.393616 | G13: 64.607567 | H13: 67.971722 | I13: 62.766443 | J13: 64.940785 | K13: 67.561957 | L13: 68.023696 | M13: 73.703858 | N13: 76.906124 | Z13: =AVERAGE(B13:N13) -> 68.571756 | AA13: =MAX(B13:N13) -> 82.509603 | AB13: =MIN(B13:Y13) -> 62.393616
A14: 8 | B14: 85.252392 | C14: 76.283935 | D14: 62.571742 | E14: 61.230544 | F14: 56.858892 | G14: 53.154807 | H14: 52.225159 | I14: 65.497455 | J14: 60.058413 | K14: 64.607567 | L14: 71.268343 | M14: 71.540676 | N14: 81.073468 | Z14: =AVERAGE(B14:N14) -> 66.278723 | AA14: =MAX(B14:N14) -> 85.252392 | AB14: =MIN(B14:Y14) -> 52.225159
A15: 9 | B15: 91.726372 | C15: 81.406521 | D15: 80.274456 | E15: 77.595485 | F15: 82.665948 | G15: 75.488162 | H15: 76.486153 | I15: 73.000894 | J15: 88.338557 | K15: 87.785499 | L15: 87.083169 | M15: 90.219867 | N15: 91.726372 | Z15: =AVERAGE(B15:N15) -> 83.369035 | AA15: =MAX(B15:N15) -> 91.726372 | AB15: =MIN(B15:Y15) -> 73.000894
A16: 10 | B16: 95.633733 | C16: 91.530741 | D16: 86.300619 | E16: 76.035418 | F16: 67.765488 | G16: 66.291788 | H16: 65.087868 | I16: 59.901259 | J16: 88.707884 | K16: 91.610286 | L16: 91.838729 | M16: 91.838729 | N16: 91.875379 | Z16: =AVERAGE(B16:N16) -> 81.878301 | AA16: =MAX(B16:N16) -> 95.633733 | AB16: =MIN(B16:Y16) -> 59.901259
A17: 11 | B17: 91.688099 | C17: 80.538518 | D17: 76.086559 | E17: 71.936122 | F17: 70.185833 | G17: 70.603838 | H17: 71.73281 | I17: 67.71214 | J17: 93.387428 | K17: 96.509206 | L17: 98.256754 | M17: 98.256754 | N17: 98.256754 | Z17: =AVERAGE(B17:N17) -> 83.47314 | AA17: =MAX(B17:N17) -> 98.256754 | AB17: =MIN(B17:Y17) -> 67.71214
A18: 12 | B18: 91.490304 | C18: 88.338557 | D18: 84.113958 | E18: 77.306313 | F18: 74.259747 | G18: 67.580322 | H18: 64.325224 | I18: 99.124696 | J18: 99.124696 | K18: 99.143244 | L18: 98.293602 | M18: 98.293602 | N18: 98.293602 | Z18: =AVERAGE(B18:N18) -> 87.668297 | AA18: =MAX(B18:N18) -> 99.143244 | AB18: =MIN(B18:Y18) -> 64.325224
... A37: 31 | B37: 91.688099 | C37: 84.113958 | D37: 70.659857 | E37: 67.71214 | F37: 65.710897 | G37: 61.251614 | H37: 59.901259 | I37: 62.526747 | J37: 61.933305 | K37: 59.142925 | L37: 59.142925 | M37: 72.643352 | N37: 82.430152 | Z37: =AVERAGE(B37:N37) -> 69.142864 | AA37: =MAX(B37:N37) -> 91.688099 | AB37: =MIN(B37:Y37) -> 59.142925
A38: Max | B38: =MAX(B7:B34) -> 96.542703 | C38: =MAX(C7:C34) -> 93.248155 | D38: =MAX(D7:D34) -> 91.783007 | E38: =MAX(E7:E34) -> 86.543747 | F38: =MAX(F7:F34) -> 82.665948 | G38: =MAX(G7:G34) -> 75.488162 | H38: =MAX(H7:H34) -> 76.486153 | I38: =MAX(I7:I34) -> 99.124696 | ... N38: =MAX(N7:N34) -> 98.293602 | Z38: =MAX(Z7:Z34) -> 87.668297 | AA38: =MAX(AA7:AA34) -> 99.143244 | AB38: =MAX(AB7:AB34) -> 73.000894
A39: Min | B39: =MIN(B7:B34) -> 79.661111 | C39: =MIN(C7:C34) -> 67.493395 | D39: =MIN(D7:D34) -> 62.501844 | E39: =MIN(E7:E34) -> 57.175946 | F39: =MIN(F7:F34) -> 54.040371 | G39: =MIN(G7:G34) -> 53.154807 | H39: =MIN(H7:H34) -> 52.225159 | I39: =MIN(I7:I34) -> 55.833676 | ... N39: =MIN(N7:N34) -> 68.90387 | Z39: =MIN(Z8:Z38) -> 63.577802 | AA39: =MIN(AA8:AA38) -> 80.103858 | AB39: =MIN(AB8:AB38) -> 52.225159
A40: X | B40: =AVERAGE(B7:B34) -> 88.793715 | C40: =AVERAGE(C7:C34) -> 82.057847 | D40: =AVERAGE(D7:D34) -> 75.038822 | E40: =AVERAGE(E7:E34) -> 70.481696 | F40: =AVERAGE(F7:F34) -> 67.136371 | G40: =AVERAGE(G7:G34) -> 64.293972 | H40: =AVERAGE(H7:H34) -> 64.894716 | I40: =AVERAGE(I7:I34) -> 67.417006 | ... N40: =AVERAGE(N7:N34) -> 84.666838 | Z40: =AVERAGE(Z9:Z39) -> 74.952308 | AA40: =AVERAGE(AA9:AA39) -> 90.050458 | AB40: =AVERAGE(AB9:AB39) -> 61.922999
Y42: Yogyakarta, 01 Februari 2021
A43: Keterangan:
B44: : Tidak ada pengamatan | Y44: =[1]COVER!X4 -> PEMBUAT LAPORAN,
Y48: Yudha Tintana Marganiswati
Y49: NIP. 198310292004122001

Sheet FEBRUARI
R2: DATA KELEMBABAN
R3: Bulan : | T3: ='[2]1'!AA1 -> FEBRUARI | V3: =JANUARI!V3 -> 2022
A5: JAM | B5: 00.00 | C5: 01.00 | D5: 02.00 | E5: 03.00 | F5: 04.00 | G5: 05.00 | H5: 06.00 | I5: 07.00 | J5: 08.00 | K5: 09.00 | L5: 10.00 | M5: 11.00 | N5: 12.00 | O5: 13.00 | P5: 14.00 | Q5: 15.00 | R5: 16.00 | S5: 17.00 | T5: 18.00 | U5: 19.00 | V5: 20.00 | W5: 21.00 | X5: 22.00 | Y5: 23.00 | Z5: rata2 | AA5: Max | AB5: Min
A6: TGL | B6: 1 | C6: 2 | D6: 3 | E6: 4 | F6: 5 | G6: 6 | H6: 7 | I6: 8 | J6: 9 | K6: 10 | L6: 11 | M6: 12 | N6: 13 | O6: 14 | P6: 15 | Q6: 16 | R6: 17 | S6: 18 | T6: 19 | U6: 20 | V6: 21 | W6: 22 | X6: 23 | Y6: 24 | Z6: 25 | AA6: 26 | AB6: 27
A7: 1 | B7: 85.320624 | C7: 79.661111 | D7: 69.432938 | E7: 65.929364 | F7: 64.253727 | G7: 64.46712 | H7: 60.653921 | I7: 54.795616 | J7: 66.934878 | K7: 71.819794 | L7: 75.106784 | M7: 78.348876 | N7: 82.149029 | Z7: =AVERAGE(B7:N7) -> 70.682599 | AA7: =MAX(B7:N7) -> 85.320624 | AB7: =MIN(B7:Y7) -> 54.795616
A8: 2 | B8: 90.107485 | C8: 78.463383 | D8: 75.158484 | E8: 70.843197 | F8: 66.336216 | G8: 69.898158 | H8: 81.324594 | I8: 83.747931 | J8: 83.822741 | K8: 80.987935 | L8: 84.254911 | M8: 82.818962 | N8: 80.987935 | Z8: =AVERAGE(B8:N8) -> 79.134764 | AA8: =MAX(B8:N8) -> 90.107485 | AB8: =MIN(B8:Y8) -> 66.336216
A9: 3 | B9: 89.152066 | C9: 82.588198 | D9: 72.026837 | E9: 66.42899 | F9: 66.336216 | G9: 56.875833 | H9: 51.67817 | I9: 88.17137 | J9: 91.366255 | K9: 91.490304 | L9: 88.338557 | M9: 89.968516 | N9: 91.530741 | Z9: =AVERAGE(B9:N9) -> 78.919389 | AA9: =MAX(B9:N9) -> 91.530741 | AB9: =MIN(B9:Y9) -> 51.67817
A10: 4 | B10: 93.263971 | C10: 87.141375 | D10: 77.403724 | E10: 71.149184 | F10: 62.5439 | G10: 62.157219 | H10: 63.272629 | I10: 63.41398 | J10: 68.163067 | K10: 63.442284 | L10: 70.659857 | M10: 76.742439 | N10: 82.188021 | Z10: =AVERAGE(B10:N10) -> 72.426281 | AA10: =MAX(B10:N10) -> 93.263971 | AB10: =MIN(B10:Y10) -> 62.157219
A11: 5 | B11: 92.272102 | C11: 90.015348 | D11: 90.152804 | E11: 85.487977 | F11: 87.227516 | G11: 85.809386 | H11: 88.758393 | I11: 87.083169 | J11: 88.656828 | K11: 87.785499 | L11: 83.969931 | M11: 91.801681 | N11: 93.326373 | Z11: =AVERAGE(B11:N11) -> 88.642077 | AA11: =MAX(B11:N11) -> 93.326373 | AB11: =MIN(B11:Y11) -> 83.969931
A12: 6 | B12: 85.520904 | C12: 74.353713 | D12: 69.689179 | E12: 68.878309 | F12: 65.846291 | G12: 65.020417 | H12: 65.728424 | I12: 94.820269 | J12: 95.686158 | K12: 94.857345 | L12: 94.857345 | M12: 94.039434 | N12: 91.530741 | Z12: =AVERAGE(B12:N12) -> 81.602195 | AA12: =MAX(B12:N12) -> 95.686158 | AB12: =MIN(B12:Y12) -> 65.020417
A13: 7 | B13: 94.067528 | C13: 89.399978 | D13: 87.757507 | E13: 88.656828 | F13: 82.341933 | G13: 81.725653 | H13: 80.274456 | I13: 78.96877 | J13: 75.488162 | K13: 77.452044 | L13: 58.773897 | M13: 65.140772 | N13: 84.184813 | Z13: =AVERAGE(B13:N13) -> 80.325565 | AA13: =MAX(B13:N13) -> 94.067528 | AB13: =MIN(B13:Y13) -> 58.773897
A14: 8 | B14: 89.202741 | C14: 84.744012 | D14: 78.510559 | E14: 72.145187 | F14: 70.485939 | G14: 60.867909 | H14: 61.467654 | I14: 62.482084 | J14: 68.491104 | K14: 73.627426 | L14: 77.689863 | M14: 77.689863 | N14: 79.929598 | Z14: =AVERAGE(B14:N14) -> 73.641072 | AA14: =MAX(B14:N14) -> 89.202741 | AB14: =MIN(B14:Y14) -> 60.867909
A15: 9 | B15: 91.726372 | C15: 87.255922 | D15: 80.792874 | E15: 71.149184 | F15: 66.564776 | G15: 63.377903 | H15: 65.846291 | I15: 61.701086 | J15: 66.15315 | K15: 84.254911 | L15: 85.714772 | M15: 85.714772 | N15: 85.520904 | Z15: =AVERAGE(B15:N15) -> 76.597917 | AA15: =MAX(B15:N15) -> 91.726372 | AB15: =MIN(B15:Y15) -> 61.701086
A16: 10 | B16: 86.046719 | C16: 84.604013 | D16: 83.497512 | E16: 66.900193 | F16: 63.890644 | G16: 63.085448 | H16: 64.878311 | I16: 61.854702 | J16: 64.593812 | K16: 66.291788 | L16: 67.244712 | M16: 76.288451 | N16: 86.874399 | Z16: =AVERAGE(B16:N16) -> 72.0039 | AA16: =MAX(B16:N16) -> 86.874399 | AB16: =MIN(B16:Y16) -> 61.854702
A17: 11 | B17: 94.881722 | C17: 92.52304 | D17: 78.696764 | E17: 64.575896 | F17: 64.521761 | G17: 64.18186 | H17: 66.765845 | I17: 65.018374 | J17: 69.004717 | K17: 94.857345 | L17: 94.832696 | M17: 93.167757 | N17: 94.832696 | Z17: =AVERAGE(B17:N17) -> 79.835421 | AA17: =MAX(B17:N17) -> 94.881722 | AB17: =MIN(B17:Y17) -> 64.18186
A18: 12 | B18: 93.167757 | C18: 85.520904 | D18: 77.306313 | E18: 73.737489 | F18: 65.012624 | G18: 60.789979 | H18: 60.058413 | I18: 62.146702 | J18: 66.564776 | K18: 67.580322 | L18: 72.145187 | M18: 75.171263 | N18: 81.15808 | Z18: =AVERAGE(B18:N18) -> 72.33537 | AA18: =MAX(B18:N18) -> 93.167757 | AB18: =MIN(B18:Y18) -> 60.058413
... A34: 28 | B34: 88.500299 | C34: 82.665948 | D34: 74.683289 | E34: 71.268343 | F34: 70.426534 | G34: 69.940096 | H34: 68.228129 | I34: 70.663522 | J34: 65.222517 | K34: 73.817406 | L34: 79.420482 | M34: 79.841062 | N34: 81.870163 | Z34: =AVERAGE(B34:N34) -> 75.119061 | AA34: =MAX(B34:N34) -> 88.500299 | AB34: =MIN(B34:Y34) -> 65.222517
A35: Max | B35: =MAX(B7:B34) -> 99.111805 | C35: =MAX(C7:C34) -> 99.118304 | D35: =MAX(D7:D34) -> 98.248313 | E35: =MAX(E7:E34) -> 98.248313 | F35: =MAX(F7:F34) -> 90.744461 | G35: =MAX(G7:G34) -> 87.02433 | H35: =MAX(H7:H34) -> 88.758393 | I35: =MAX(I7:I34) -> 94.820269 | ... N35: =MAX(N7:N34) -> 100 | Z35: =MAX(Z7:Z34) -> 88.642077 | AA35: =MAX(AA7:AA34) -> 100 | AB35: =MAX(AB7:AB34) -> 83.969931
A36: Min | B36: =MIN(B8:B35) -> 69.616433 | C36: =MIN(C8:C35) -> 68.630726 | D36: =MIN(D8:D35) -> 61.528243 | E36: =MIN(E8:E35) -> 58.411183 | F36: =MIN(F8:F35) -> 56.425985 | G36: =MIN(G8:G35) -> 56.875833 | H36: =MIN(H8:H35) -> 51.67817 | I36: =MIN(I8:I35) -> 59.50557 | ... N36: =MIN(N8:N35) -> 71.808435 | Z36: =MIN(Z8:Z35) -> 66.717828 | AA36: =MIN(AA8:AA35) -> 79.661111 | AB36: =MIN(AB8:AB35) -> 51.67817
A37: X | B37: =AVERAGE(B7:B34) -> 89.343997 | C37: =AVERAGE(C7:C34) -> 84.341135 | D37: =AVERAGE(D7:D34) -> 78.614137 | E37: =AVERAGE(E7:E34) -> 73.109861 | F37: =AVERAGE(F7:F34) -> 69.782097 | G37: =AVERAGE(G7:G34) -> 67.493483 | H37: =AVERAGE(H7:H34) -> 67.808671 | I37: =AVERAGE(I7:I34) -> 70.332993 | ... N37: =AVERAGE(N7:N34) -> 86.055067 | Z37: =AVERAGE(Z9:Z36) -> 77.116683 | AA37: =AVERAGE(AA9:AA36) -> 91.740051 | AB37: =AVERAGE(AB9:AB36) -> 64.138653
A40: Keterangan:
B41: : Tidak ada pengamatan
Y43: Yogyakarta, 01 Maret 2022
Y45: =[1]COVER!X4 -> PEMBUAT LAPORAN,
Y49: Yudha Tintana Marganiswati
Y50: NIP. 198310292004122001

Sheet MARET
R2: DATA KELEMBABAN
R3: Bulan : | T3: ='[3]1'!AA1 -> MARET | V3: =JANUARI!V3 -> 2022
A5: JAM | B5: 00.00 | C5: 01.00 | D5: 02.00 | E5: 03.00 | F5: 04.00 | G5: 05.00 | H5: 06.00 | I5: 07.00 | J5: 08.00 | K5: 09.00 | L5: 10.00 | M5: 11.00 | N5: 12.00 | O5: 13.00 | P5: 14.00 | Q5: 15.00 | R5: 16.00 | S5: 17.00 | T5: 18.00 | U5: 19.00 | V5: 20.00 | W5: 21.00 | X5: 22.00 | Y5: 23.00 | Z5: rata2 | AA5: Max | AB5: Min
A6: TGL | B6: 1 | C6: 2 | D6: 3 | E6: 4 | F6: 5 | G6: 6 | H6: 7 | I6: 8 | J6: 9 | K6: 10 | L6: 11 | M6: 12 | N6: 13 | O6: 14 | P6: 15 | Q6: 16 | R6: 17 | S6: 18 | T6: 19 | U6: 20 | V6: 21 | W6: 22 | X6: 23 | Y6: 24 | Z6: 25 | AA6: 26 | AB6: 27
A7: 1 | B7: 81.934745 | C7: 75.508764 | D7: 70.534263 | E7: 59.8641 | F7: 56.773205 | G7: 58.202923 | H7: 62.692643 | I7: 61.701086 | J7: 66.661614 | K7: 77.50011 | L7: 75.278017 | M7: 78.650584 | N7: 81.324594 | Z7: =AVERAGE(B7:N7) -> 69.740511 | AA7: =MAX(B7:N7) -> 81.934745 | AB7: =MIN(B7:Y7) -> 56.773205
A8: 2 | B8: 85.252392 | C8: 79.661111 | D8: 69.432938 | E8: 68.359313 | F8: 72.262296 | G8: 76.288451 | H8: 80.06064 | I8: 90.197634 | J8: 94.929678 | K8: 88.707884 | L8: 90.977681 | M8: 94.905832 | N8: 97.402347 | Z8: =AVERAGE(B8:N8) -> 83.726015 | AA8: =MAX(B8:N8) -> 97.402347 | AB8: =MIN(B8:Y8) -> 68.359313
A9: 3 | B9: 83.479517 | C9: 73.897493 | D9: 67.215482 | E9: 68.226129 | F9: 69.940096 | G9: 73.954201 | H9: 75.106784 | I9: 74.526912 | J9: 77.547923 | K9: 79.375896 | L9: 83.533973 | M9: 90.241981 | N9: 94.163464 | Z9: =AVERAGE(B9:N9) -> 77.785373 | AA9: =MAX(B9:N9) -> 94.163464 | AB9: =MIN(B9:Y9) -> 67.215482
A10: 4 | B10: 89.152066 | C10: 81.15808 | D10: 73.98548 | E10: 70.41955 | F10: 70.968094 | G10: 68.548434 | H10: 65.998049 | I10: 70.185833 | J10: 72.492861 | K10: 81.567779 | L10: 85.840588 | M10: 85.778016 | N10: 87.198956 | Z10: =AVERAGE(B10:N10) -> 77.176445 | AA10: =MAX(B10:N10) -> 89.152066 | AB10: =MIN(B10:Y10) -> 65.998049
A11: 5 | B11: 93.232253 | C11: 84.113958 | D11: 73.290208 | E11: 74.313741 | F11: 71.502977 | G11: 74.420883 | H11: 73.403802 | I11: 73.737489 | J11: 74.89726 | K11: 77.50011 | L11: 81.406521 | M11: 82.742866 | N11: 82.588198 | Z11: =AVERAGE(B11:N11) -> 78.242328 | AA11: =MAX(B11:N11) -> 93.232253 | AB11: =MIN(B11:Y11) -> 71.502977
A12: 6 | B12: 92.234637 | C12: 86.843918 | D12: 74.844084 | E12: 69.302774 | F12: 67.03909 | G12: 66.661614 | H12: 67.8426 | I12: 65.087868 | J12: 65.929364 | K12: 67.965836 | L12: 71.463418 | M12: 77.831603 | N12: 83.386947 | Z12: =AVERAGE(B12:N12) -> 73.571827 | AA12: =MAX(B12:N12) -> 92.234637 | AB12: =MIN(B12:Y12) -> 65.087868
A13: 7 | B13: 93.263971 | C13: 84.778539 | D13: 78.320329 | E13: 75.224782 | F13: 69.087683 | G13: 70.00201 | H13: 68.556484 | I13: 70.063603 | J13: 71.208919 | K13: 70.970344 | L13: 74.353713 | M13: 85.650845 | N13: 90.241981 | Z13: =AVERAGE(B13:N13) -> 77.055631 | AA13: =MAX(B13:N13) -> 93.263971 | AB13: =MIN(B13:Y13) -> 68.556484
A14: 8 | B14: 88.338557 | C14: 87.141375 | D14: 78.023197 | E14: 74.313741 | F14: 73.627426 | G14: 70.063603 | H14: 69.129825 | I14: 67.529393 | J14: 67.907327 | K14: 72.378181 | L14: 73.627426 | M14: 85.778016 | N14: 88.758393 | Z14: =AVERAGE(B14:N14) -> 76.662805 | AA14: =MAX(B14:N14) -> 88.758393 | AB14: =MIN(B14:Y14) -> 67.529393
A15: 9 | B15: 95.776939 | C15: 95.022498 | D15: 90.241981 | E15: 77.879885 | F15: 76.387819 | G15: 76.583469 | H15: 73.388541 | I15: 74.374395 | J15: 75.158484 | K15: 81.725653 | L15: 79.286008 | M15: 85.840588 | N15: 90.219867 | Z15: =AVERAGE(B15:N15) -> 82.452779 | AA15: =MAX(B15:N15) -> 95.776939 | AB15: =MIN(B15:Y15) -> 73.388541
A16: 10 | B16: 99.128898 | C16: 96.575466 | D16: 90.263975 | E16: 76.642437 | F16: 76.288451 | G16: 81.956325 | H16: 77.179643 | I16: 71.502977 | J16: 73.846409 | K16: 76.288451 | L16: 81.487579 | M16: 82.818962 | N16: 91.764231 | Z16: =AVERAGE(B16:N16) -> 82.749523 | AA16: =MAX(B16:N16) -> 99.128898 | AB16: =MIN(B16:Y16) -> 71.502977
A17: 11 | B17: 93.982305 | C17: 91.610286 | D17: 82.818962 | E17: 77.50011 | F17: 73.168395 | G17: 70.246475 | H17: 66.564776 | I17: 64.18186 | J17: 77.403724 | K17: 82.818962 | L17: 91.570733 | M17: 91.570733 | N17: 91.570733 | Z17: =AVERAGE(B17:N17) -> 81.154466 | AA17: =MAX(B17:N17) -> 93.982305 | AB17: =MIN(B17:Y17) -> 64.18186
A18: 12 | B18: 89.152066 | C18: 83.969931 | D18: 81.647133 | E18: 74.367452 | F18: 69.530874 | G18: 71.618485 | H18: 70.306805 | I18: 73.333932 | J18: 74.790838 | K18: 93.341761 | L18: 97.420848 | M18: 97.426948 | N18: 96.583544 | Z18: =AVERAGE(B18:N18) -> 82.576201 | AA18: =MAX(B18:N18) -> 97.426948 | AB18: =MIN(B18:Y18) -> 69.530874
... A37: 31 | B37: 86.399004 | C37: 87.349053 | D37: 73.473087 | E37: 69.432938 | F37: 65.012624 | G37: 62.006739 | H37: 63.129839 | I37: 65.631232 | J37: 67.158816 | K37: 70.426534 | L37: 75.693926 | M37: 80.917038 | N37: 81.950911 | Z37: =AVERAGE(B37:N37) -> 72.967826 | AA37: =MAX(B37:N37) -> 87.349053 | AB37: =MIN(B37:Y37) -> 62.006739
A38: Max | B38: =MAX(B7:B37) -> 99.128898 | C38: =MAX(C7:C37) -> 96.591577 | D38: =MAX(D7:D37) -> 94.905832 | E38: =MAX(E7:E37) -> 98.265101 | F38: =MAX(F7:F37) -> 92.470883 | G38: =MAX(G7:G37) -> 81.956325 | H38: =MAX(H7:H37) -> 87.000035 | I38: =MAX(I7:I37) -> 90.197634 | ... N38: =MAX(N7:N37) -> 98.222417 | Z38: =MAX(Z7:Z37) -> 87.778196 | AA38: =MAX(AA7:AA37) -> 99.128898 | AB38: =MAX(AB7:AB37) -> 76.231616
A39: Min | B39: =MIN(B7:B37) -> 81.934745 | C39: =MIN(C7:C37) -> 73.897493 | D39: =MIN(D7:D37) -> 67.215482 | E39: =MIN(E7:E37) -> 59.8641 | F39: =MIN(F7:F37) -> 56.773205 | G39: =MIN(G7:G37) -> 58.202923 | H39: =MIN(H7:H37) -> 58.013565 | I39: =MIN(I7:I37) -> 60.239018 | ... N39: =MIN(N7:N37) -> 79.661111 | Z39: =MIN(Z8:Z38) -> 72.60624 | AA39: =MIN(AA8:AA38) -> 85.183405 | AB39: =MIN(AB8:AB38) -> 58.013565
A40: X | B40: =AVERAGE(B7:B37) -> 90.40483 | C40: =AVERAGE(C7:C37) -> 85.433819 | D40: =AVERAGE(D7:D37) -> 78.960524 | E40: =AVERAGE(E7:E37) -> 73.950724 | F40: =AVERAGE(F7:F37) -> 70.286992 | G40: =AVERAGE(G7:G37) -> 69.80124 | H40: =AVERAGE(H7:H37) -> 69.515673 | I40: =AVERAGE(I7:I37) -> 70.267632 | ... N40: =AVERAGE(N7:N37) -> 89.683906 | Z40: =AVERAGE(Z9:Z39) -> 78.961119 | AA40: =AVERAGE(AA9:AA39) -> 92.933012 | AB40: =AVERAGE(AB9:AB39) -> 66.850242
A43: Keterangan:
B44: : Tidak ada pengamatan
Y46: Yogyakarta, 06 April 2022
Y48: =[1]COVER!X4 -> PEMBUAT LAPORAN,
Y52: Yudha Tintana Marganiswati
Y53: NIP. 198310292004122001

Sheet APRIL
R2: DATA KELEMBABAN
R3: Bulan : | T3: ='[4]1'!AA1 -> APRIL | V3: =JANUARI!V3 -> 2022
A5: JAM | B5: 00.00 | C5: 01.00 | D5: 02.00 | E5: 03.00 | F5: 04.00 | G5: 05.00 | H5: 06.00 | I5: 07.00 | J5: 08.00 | K5: 09.00 | L5: 10.00 | M5: 11.00 | N5: 12.00 | O5: 13.00 | P5: 14.00 | Q5: 15.00 | R5: 16.00 | S5: 17.00 | T5: 18.00 | U5: 19.00 | V5: 20.00 | W5: 21.00 | X5: 22.00 | Y5: 23.00 | Z5: rata2 | AA5: Max | AB5: Min
A6: TGL | B6: 1 | C6: 2 | D6: 3 | E6: 4 | F6: 5 | G6: 6 | H6: 7 | I6: 8 | J6: 9 | K6: 10 | L6: 11 | M6: 12 | N6: 13 | O6: 14 | P6: 15 | Q6: 16 | R6: 17 | S6: 18 | T6: 19 | U6: 20 | V6: 21 | W6: 22 | X6: 23 | Y6: 24 | Z6: 25 | AA6: 26 | AB6: 27
A7: 1 | B7: 88.283444 | C7: 82.588198 | D7: 69.038259 | E7: 66.291788 | F7: 67.971722 | G7: 60.058413 | H7: 61.701086 | I7: 59.090728 | J7: 58.120518 | K7: 78.924031 | L7: 98.256754 | M7: 98.244057 | N7: 98.248313 | Z7: =AVERAGE(B7:N7) -> 75.909024 | AA7: =MAX(B7:N7) -> 98.256754 | AB7: =MIN(B7:Y7) -> 58.120518
A8: 2 | B8: 87.939569 | C8: 78.916684 | D8: 70.784128 | E8: 69.561734 | F8: 67.069391 | G8: 63.521897 | H8: 60.36795 | I8: 58.688594 | J8: 72.492861 | K8: 80.85788 | L8: 97.318498 | M8: 93.864152 | N8: 94.76986 | Z8: =AVERAGE(B8:N8) -> 76.627169 | AA8: =MAX(B8:N8) -> 97.318498 | AB8: =MIN(B8:Y8) -> 58.688594
A9: 3 | B9: 95.696469 | C9: 91.707288 | D9: 78.604157 | E9: 75.00257 | F9: 67.580322 | G9: 67.39965 | H9: 68.750584 | I9: 68.750584 | J9: 74.683289 | K9: 96.559175 | L9: 98.231146 | M9: 98.231146 | N9: 98.231146 | Z9: =AVERAGE(B9:N9) -> 83.032887 | AA9: =MAX(B9:N9) -> 98.231146 | AB9: =MIN(B9:Y9) -> 67.39965
A10: 4 | B10: 89.126519 | C10: 76.488328 | D10: 74.353713 | E10: 72.262296 | F10: 69.940096 | G10: 67.971722 | H10: 67.39965 | I10: 70.185833 | J10: 68.878309 | K10: 68.750584 | L10: 80.189608 | M10: 81.567779 | N10: 85.714772 | Z10: =AVERAGE(B10:N10) -> 74.833016 | AA10: =MAX(B10:N10) -> 89.126519 | AB10: =MIN(B10:Y10) -> 67.39965
A11: 5 | B11: 93.326373 | C11: 82.665948 | D11: 79.286008 | E11: 71.028774 | F11: 71.149184 | G11: 75.311982 | H11: 73.442868 | I11: 73.550684 | J11: 72.378181 | K11: 75.106784 | L11: 80.103858 | M11: 83.497512 | N11: 87.141375 | Z11: =AVERAGE(B11:N11) -> 78.306887 | AA11: =MAX(B11:N11) -> 93.326373 | AB11: =MIN(B11:Y11) -> 71.028774
A12: 6 | B12: 94.067528 | C12: 87.89596 | D12: 73.516202 | E12: 72.378181 | F12: 64.521761 | G12: 64.521761 | H12: 64.46712 | I12: 62.936946 | J12: 68.421304 | K12: 70.00201 | L12: 75.540009 | M12: 80.103858 | N12: 85.048146 | Z12: =AVERAGE(B12:N12) -> 74.109291 | AA12: =MAX(B12:N12) -> 94.067528 | AB12: =MIN(B12:Y12) -> 62.936946
A13: 7 | B13: 83.595823 | C13: 79.569669 | D13: 75.775603 | E13: 73.290208 | F13: 81.567779 | G13: 81.725653 | H13: 75.106784 | I13: 72.886679 | J13: 71.268343 | K13: 72.538695 | L13: 81.324594 | M13: 86.238178 | N13: 90.809467 | Z13: =AVERAGE(B13:N13) -> 78.899806 | AA13: =MAX(B13:N13) -> 90.809467 | AB13: =MIN(B13:Y13) -> 71.268343
A14: 8 | B14: 90.76625 | C14: 86.964848 | D14: 81.241784 | E14: 74.24149 | F14: 76.086559 | G14: 74.790838 | H14: 73.11264 | I14: 71.268343 | J14: 73.737489 | K14: 72.145187 | L14: 78.650584 | M14: 81.324594 | N14: 85.520904 | Z14: =AVERAGE(B14:N14) -> 78.450116 | AA14: =MAX(B14:N14) -> 90.76625 | AB14: =MIN(B14:Y14) -> 71.268343
A15: 9 | B15: 92.272102 | C15: 85.586225 | D15: 82.627178 | E15: 74.737206 | F15: 72.378181 | G15: 70.542172 | H15: 72.60635 | I15: 71.020106 | J15: 71.936122 | K15: 71.386269 | L15: 78.070462 | M15: 81.241784 | N15: 87.255922 | Z15: =AVERAGE(B15:N15) -> 77.820006 | AA15: =MAX(B15:N15) -> 92.272102 | AB15: =MIN(B15:Y15) -> 70.542172
A16: 10 | B16: 88.605218 | C16: 77.108358 | D16: 72.203895 | E16: 70.542172 | F16: 66.269276 | G16: 65.998049 | H16: 70.662337 | I16: 70.426534 | J16: 94.929678 | K16: 96.559175 | L16: 98.256754 | M16: 98.256754 | N16: 98.256754 | Z16: =AVERAGE(B16:N16) -> 82.159612 | AA16: =MAX(B16:N16) -> 98.256754 | AB16: =MIN(B16:Y16) -> 65.998049
A17: 11 | B17: 91.490304 | C17: 90.061668 | D17: 77.50011 | E17: 71.268343 | F17: 66.832181 | G17: 63.664428 | H17: 61.551605 | I17: 73.516202 | J17: 70.54504 | K17: 79.195158 | L17: 85.714772 | M17: 89.471759 | N17: 90.197634 | Z17: =AVERAGE(B17:N17) -> 77.769939 | AA17: =MAX(B17:N17) -> 91.490304 | AB17: =MIN(B17:Y17) -> 61.551605
A18: 12 | B18: 92.30915 | C18: 84.042334 | D18: 78.7427 | E18: 62.482084 | F18: 59.582067 | G18: 56.185806 | H18: 53.445209 | I18: 51.765991 | J18: 66.832181 | K18: 77.50011 | L18: 80.189608 | M18: 72.823564 | N18: 74.013398 | Z18: =AVERAGE(B18:N18) -> 69.9934 | AA18: =MAX(B18:N18) -> 92.30915 | AB18: =MIN(B18:Y18) -> 51.765991
... A36: 30 | B36: 93.417462 | C36: 85.902496 | D36: 80.358414 | E36: 77.642798 | F36: 71.618485 | G36: 70.54504 | H36: 65.763663 | I36: 63.553913 | J36: 76.286129 | K36: 80.85788 | L36: 85.320624 | M36: 89.22787 | N36: 90.015348 | Z36: =AVERAGE(B36:N36) -> 79.270009 | AA36: =MAX(B36:N36) -> 93.417462 | AB36: =MIN(B36:Y36) -> 63.553913
A37: Max | B37: =MAX(B7:B36) -> 96.623276 | C37: =MAX(C7:C36) -> 93.263971 | D37: =MAX(D7:D36) -> 88.526744 | E37: =MAX(E7:E36) -> 84.392875 | F37: =MAX(F7:F36) -> 81.567779 | G37: =MAX(G7:G36) -> 81.725653 | H37: =MAX(H7:H36) -> 84.256734 | I37: =MAX(I7:I36) -> 90.498296 | ... N37: =MAX(N7:N36) -> 98.256754 | Z37: =MAX(Z7:Z36) -> 85.66455 | AA37: =MAX(AA7:AA36) -> 99.111805 | AB37: =MAX(AB7:AB36) -> 74.166462
A38: Min | B38: =MIN(B7:B36) -> 83.321396 | C38: =MIN(C7:C36) -> 76.488328 | D38: =MIN(D7:D36) -> 69.038259 | E38: =MIN(E7:E36) -> 62.482084 | F38: =MIN(F7:F36) -> 58.711933 | G38: =MIN(G7:G36) -> 55.890144 | H38: =MIN(H7:H36) -> 49.291852 | I38: =MIN(I7:I36) -> 47.832794 | ... N38: =MIN(N7:N36) -> 74.013398 | Z38: =MIN(Z8:Z37) -> 67.543774 | AA38: =MIN(AA8:AA37) -> 86.690499 | AB38: =MIN(AB8:AB37) -> 47.832794
A39: X | B39: =AVERAGE(B7:B36) -> 90.324642 | C39: =AVERAGE(C7:C36) -> 83.810516 | D39: =AVERAGE(D7:D36) -> 76.753055 | E39: =AVERAGE(E7:E36) -> 71.370639 | F39: =AVERAGE(F7:F36) -> 67.774225 | G39: =AVERAGE(G7:G36) -> 65.337081 | H39: =AVERAGE(H7:H36) -> 66.197386 | I39: =AVERAGE(I7:I36) -> 68.033792 | ... N39: =AVERAGE(N7:N36) -> 90.051713 | Z39: =AVERAGE(Z9:Z38) -> 77.561202 | AA39: =AVERAGE(AA9:AA38) -> 92.981941 | AB39: =AVERAGE(AB9:AB38) -> 63.324651
A42: Keterangan:
B43: : Tidak ada pengamatan
Y45: Yogyakarta, 01 Mei 2021
Y47: =[1]COVER!X4 -> PEMBUAT LAPORAN,
Y51: Yudha Tintana Marganiswati
Y52: NIP. 198310292004122001

Sheet MEI
R2: DATA KELEMBABAN
R3: Bulan : | T3: ='[5]1'!AA1 -> MEI | V3: =JANUARI!V3 -> 2022
A5: JAM | B5: 00.00 | C5: 01.00 | D5: 02.00 | E5: 03.00 | F5: 04.00 | G5: 05.00 | H5: 06.00 | I5: 07.00 | J5: 08.00 | K5: 09.00 | L5: 10.00 | M5: 11.00 | N5: 12.00 | O5: 13.00 | P5: 14.00 | Q5: 15.00 | R5: 16.00 | S5: 17.00 | T5: 18.00 | U5: 19.00 | V5: 20.00 | W5: 21.00 | X5: 22.00 | Y5: 23.00 | Z5: rata2 | AA5: Max | AB5: Min
A6: TGL | B6: 1 | C6: 2 | D6: 3 | E6: 4 | F6: 5 | G6: 6 | H6: 7 | I6: 8 | J6: 9 | K6: 10 | L6: 11 | M6: 12 | N6: 13 | O6: 14 | P6: 15 | Q6: 16 | R6: 17 | S6: 18 | T6: 19 | U6: 20 | V6: 21 | W6: 22 | X6: 23 | Y6: 24 | Z6: 25 | AA6: 26 | AB6: 27
A7: 1 | B7: ='[6]input data'!H6 -> 89.277716 | C7: ='[6]input data'!H7 -> 76.490431 | D7: ='[6]input data'!H8 -> 70.968094 | E7: ='[6]input data'!H9 -> 67.069391 | F7: ='[6]input data'!H10 -> 66.665843 | G7: ='[6]input data'!H11 -> 69.736488 | H7: ='[6]input data'!H12 -> 54.62526 | I7: ='[6]input data'!H13 -> 53.225477 | J7: ='[6]input data'!H14 -> 60.36795 | K7: ='[6]input data'!H15 -> 76.486153 | L7: ='[6]input data'!H16 -> 90.329253 | M7: ='[6]input data'!H17 -> 90.197634 | N7: ='[6]input data'!H18 -> 91.764231 | Z7: =AVERAGE(B7:N7) -> 73.631071 | AA7: =MAX(B7:N7) -> 91.764231 | AB7: =MIN(B7:Y7) -> 53.225477
A8: 2 | B8: ='[6]input data'!H42 -> 88.758393 | C8: ='[6]input data'!H43 -> 84.460763 | D8: ='[6]input data'!H44 -> 78.439747 | E8: ='[6]input data'!H45 -> 79.529624 | F8: ='[6]input data'!H46 -> 71.308961 | G8: ='[6]input data'!H47 -> 63.945186 | H8: ='[6]input data'!H48 -> 58.348409 | I8: ='[6]input data'!H49 -> 57.842134 | J8: ='[6]input data'!H50 -> 70.085993 | K8: ='[6]input data'!H51 -> 90.015348 | L8: ='[6]input data'!H52 -> 75.984005 | M8: ='[6]input data'!H53 -> 77.207863 | N8: ='[6]input data'!H54 -> 79.751571 | Z8: =AVERAGE(B8:N8) -> 75.052154 | AA8: =MAX(B8:N8) -> 90.015348 | AB8: =MIN(B8:Y8) -> 57.842134
A9: 3 | B9: ='[6]input data'!H78 -> 84.184813 | C9: ='[6]input data'!H79 -> 78.650584 | D9: ='[6]input data'!H80 -> 73.627426 | E9: ='[6]input data'!H81 -> 66.42899 | F9: ='[6]input data'!H82 -> 60.945439 | G9: ='[6]input data'!H83 -> 53.04816 | H9: ='[6]input data'!H84 -> 48.797021 | I9: ='[6]input data'!H85 -> 55.002618 | J9: ='[6]input data'!H86 -> 64.220333 | K9: ='[6]input data'!H87 -> 64.220333 | L9: ='[6]input data'!H88 -> 75.709873 | M9: ='[6]input data'!H89 -> 83.46873 | N9: ='[6]input data'!H90 -> 83.258933 | Z9: =AVERAGE(B9:N9) -> 68.581789 | AA9: =MAX(B9:N9) -> 84.184813 | AB9: =MIN(B9:Y9) -> 48.797021
A10: 4 | B10: ='[6]input data'!H114 -> 94.99967 | C10: ='[6]input data'!H115 -> 80.95799 | D10: ='[6]input data'!H116 -> 68.357245 | E10: ='[6]input data'!H117 -> 62.006739 | F10: ='[6]input data'!H118 -> 57.531256 | G10: ='[6]input data'!H119 -> 58.348409 | H10: ='[6]input data'!H120 -> 59.350053 | I10: ='[6]input data'!H121 -> 53.688306 | J10: ='[6]input data'!H122 -> 52.778793 | K10: ='[6]input data'!H123 -> 73.525234 | L10: ='[6]input data'!H124 -> 74.787219 | M10: ='[6]input data'!H125 -> 83.95671 | N10: ='[6]input data'!H126 -> 90.559862 | Z10: =AVERAGE(B10:N10) -> 70.065191 | AA10: =MAX(B10:N10) -> 94.99967 | AB10: =MIN(B10:Y10) -> 52.778793
A11: 5 | B11: ='[6]input data'!H150 -> 94.229785 | C11: ='[6]input data'!H151 -> 84.324261 | D11: ='[6]input data'!H152 -> 79.101586 | E11: ='[6]input data'!H153 -> 74.683904 | F11: ='[6]input data'!H154 -> 70.426534 | G11: ='[6]input data'!H155 -> 66.336216 | H11: ='[6]input data'!H156 -> 67.350844 | I11: ='[6]input data'!H157 -> 73.76302 | J11: ='[6]input data'!H158 -> 69.004717 | K11: ='[6]input data'!H159 -> 86.453798 | L11: ='[6]input data'!H160 -> 86.573411 | M11: ='[6]input data'!H161 -> 87.284176 | N11: ='[6]input data'!H162 -> 88.758393 | Z11: =AVERAGE(B11:N11) -> 79.09928 | AA11: =MAX(B11:N11) -> 94.229785 | AB11: =MIN(B11:Y11) -> 66.336216
A12: 6 | B12: ='[6]input data'!H186 -> 87.083169 | C12: ='[6]input data'!H187 -> 82.265385 | D12: ='[6]input data'!H188 -> 76.583469 | E12: ='[6]input data'!H189 -> 72.829825 | F12: ='[6]input data'!H190 -> 65.980311 | G12: ='[6]input data'!H191 -> 67.784936 | H12: ='[6]input data'!H192 -> 68.158654 | I12: ='[6]input data'!H193 -> 96.623276 | J12: ='[6]input data'!H194 -> 90.197634 | K12: ='[6]input data'!H195 -> 88.857799 | L12: ='[6]input data'!H196 -> 94.881722 | M12: ='[6]input data'!H197 -> 96.542703 | N12: ='[6]input data'!H198 -> 93.167757 | Z12: =AVERAGE(B12:N12) -> 83.150511 | AA12: =MAX(B12:N12) -> 96.623276 | AB12: =MIN(B12:Y12) -> 65.980311
A13: 7 | B13: ='[6]input data'!H222 -> 95.04508 | C13: ='[6]input data'!H223 -> 84.460763 | D13: ='[6]input data'!H224 -> 80.441495 | E13: ='[6]input data'!H225 -> 74.270962 | F13: ='[6]input data'!H226 -> 71.957973 | G13: ='[6]input data'!H227 -> 71.119776 | H13: ='[6]input data'!H228 -> 68.59788 | I13: ='[6]input data'!H229 -> 72.068844 | J13: ='[6]input data'!H230 -> 75.412996 | K13: ='[6]input data'!H231 -> 86.024359 | L13: ='[6]input data'!H232 -> 94.929678 | M13: ='[6]input data'!H233 -> 94.857345 | N13: ='[6]input data'!H234 -> 94.857345 | Z13: =AVERAGE(B13:N13) -> 81.849577 | AA13: =MAX(B13:N13) -> 95.04508 | AB13: =MIN(B13:Y13) -> 68.59788
A14: 8 | B14: ='[6]input data'!H258 -> 89.375791 | C14: ='[6]input data'!H259 -> 85.902496 | D14: ='[6]input data'!H260 -> 80.441495 | E14: ='[6]input data'!H261 -> 75.512973 | F14: ='[6]input data'!H262 -> 75.611927 | G14: ='[6]input data'!H263 -> 70.778443 | H14: ='[6]input data'!H264 -> 71.957973 | I14: ='[6]input data'!H265 -> 71.502977 | J14: ='[6]input data'!H266 -> 83.364651 | K14: ='[6]input data'!H267 -> 92.171645 | L14: ='[6]input data'!H268 -> 88.161929 | M14: ='[6]input data'!H269 -> 92.707184 | N14: ='[6]input data'!H270 -> 95.111388 | Z14: =AVERAGE(B14:N14) -> 82.507759 | AA14: =MAX(B14:N14) -> 95.111388 | AB14: =MIN(B14:Y14) -> 70.778443
A15: 9 | B15: ='[6]input data'!H294 -> 88.553044 | C15: ='[6]input data'!H295 -> 81.406521 | D15: ='[6]input data'!H296 -> 77.132075 | E15: ='[6]input data'!H297 -> 74.889474 | F15: ='[6]input data'!H298 -> 64.152064 | G15: ='[6]input data'!H299 -> 65.088012 | H15: ='[6]input data'!H300 -> 73.087971 | I15: ='[6]input data'!H301 -> 95.891246 | J15: ='[6]input data'!H302 -> 88.808362 | K15: ='[6]input data'!H303 -> 87.531809 | L15: ='[6]input data'!H304 -> 90.456707 | M15: ='[6]input data'!H305 -> 90.456707 | N15: ='[6]input data'!H306 -> 91.983003 | Z15: =AVERAGE(B15:N15) -> 82.264384 | AA15: =MAX(B15:N15) -> 95.891246 | AB15: =MIN(B15:Y15) -> 64.152064
A16: 10 | B16: ='[6]input data'!H330 -> 91.801681 | C16: ='[6]input data'!H331 -> 84.460763 | D16: ='[6]input data'!H332 -> 76.486153 | E16: ='[6]input data'!H333 -> 71.73281 | F16: ='[6]input data'!H334 -> 67.848012 | G16: ='[6]input data'!H335 -> 66.630439 | H16: ='[6]input data'!H336 -> 68.958644 | I16: ='[6]input data'!H337 -> 69.736488 | J16: ='[6]input data'!H338 -> 74.476775 | K16: ='[6]input data'!H339 -> 76.727563 | L16: ='[6]input data'!H340 -> 76.592038 | M16: ='[6]input data'!H341 -> 85.015075 | N16: ='[6]input data'!H342 -> 89.542389 | Z16: =AVERAGE(B16:N16) -> 76.923756 | AA16: =MAX(B16:N16) -> 91.801681 | AB16: =MIN(B16:Y16) -> 66.630439
A17: 11 | B17: ='[6]input data'!H366 -> 86.362387 | C17: ='[6]input data'!H367 -> 80.189608 | D17: ='[6]input data'!H368 -> 74.787219 | E17: ='[6]input data'!H369 -> 69.376214 | F17: ='[6]input data'!H370 -> 65.088012 | G17: ='[6]input data'!H371 -> 66.503016 | H17: ='[6]input data'!H372 -> 64.083452 | I17: ='[6]input data'!H373 -> 62.275612 | J17: ='[6]input data'!H374 -> 58.663836 | K17: ='[6]input data'!H375 -> 78.496631 | L17: ='[6]input data'!H376 -> 82.325153 | M17: ='[6]input data'!H377 -> 84.789659 | N17: ='[6]input data'!H378 -> 86.084332 | Z17: =AVERAGE(B17:N17) -> 73.771164 | AA17: =MAX(B17:N17) -> 86.362387 | AB17: =MIN(B17:Y17) -> 58.663836
A18: 12 | B18: ='[6]input data'!H402 -> 91.820255 | C18: ='[6]input data'!H403 -> 91.929622 | D18: ='[6]input data'!H404 -> 79.057546 | E18: ='[6]input data'!H405 -> 69.004717 | F18: ='[6]input data'!H406 -> 72.994429 | G18: ='[6]input data'!H407 -> 71.701196 | H18: ='[6]input data'!H408 -> 69.677202 | I18: ='[6]input data'!H409 -> 63.168735 | J18: ='[6]input data'!H410 -> 65.745622 | K18: ='[6]input data'!H411 -> 67.726283 | L18: ='[6]input data'!H412 -> 79.529624 | M18: ='[6]input data'!H413 -> 84.5944 | N18: ='[6]input data'!H414 -> 87.31228 | Z18: =AVERAGE(B18:N18) -> 76.481686 | AA18: =MAX(B18:N18) -> 91.929622 | AB18: =MIN(B18:Y18) -> 63.168735
A19: 13 | B19: ='[6]input data'!H438 -> 76.742439 | C19: ='[6]input data'!H439 -> 75.106784 | D19: ='[6]input data'!H440 -> 70.306805 | E19: ='[6]input data'!H441 -> 65.980311 | F19: ='[6]input data'!H442 -> 57.36275 | G19: ='[6]input data'!H443 -> 57.039869 | H19: ='[6]input data'!H444 -> 51.770126 | I19: ='[6]input data'!H445 -> 56.336067 | J19: ='[6]input data'!H446 -> 67.545774 | K19: ='[6]input data'!H447 -> 72.554849 | L19: ='[6]input data'!H448 -> 79.232336 | M19: ='[6]input data'!H449 -> 80.624211 | N19: ='[6]input data'!H450 -> 92.52304 | Z19: =AVERAGE(B19:N19) -> 69.471182 | AA19: =MAX(B19:N19) -> 92.52304 | AB19: =MIN(B19:Y19) -> 51.770126
A20: 14 | B20: ='[6]input data'!H474 -> 88.783444 | C20: ='[6]input data'!H475 -> 80.441495 | D20: ='[6]input data'!H476 -> 71.502977 | E20: ='[6]input data'!H477 -> 68.351235 | F20: ='[6]input data'!H478 -> 65.020417 | G20: ='[6]input data'!H479 -> 68.59788 | H20: ='[6]input data'!H480 -> 73.263206 | I20: ='[6]input data'!H481 -> 74.527575 | J20: ='[6]input data'!H482 -> 74.735695 | K20: ='[6]input data'!H483 -> 79.275468 | L20: ='[6]input data'!H484 -> 85.46247 | M20: ='[6]input data'!H485 -> 87.558603 | N20: ='[6]input data'!H486 -> 87.89596 | Z20: =AVERAGE(B20:N20) -> 77.339725 | AA20: =MAX(B20:N20) -> 88.783444 | AB20: =MIN(B20:Y20) -> 65.020417
A21: 15 | B21: ='[6]input data'!H510 -> 93.447174 | C21: ='[6]input data'!H511 -> 77.783259 | D21: ='[6]input data'!H512 -> 76.486153 | E21: ='[6]input data'!H513 -> 72.939843 | F21: ='[6]input data'!H514 -> 68.351235 | G21: ='[6]input data'!H515 -> 66.244302 | H21: ='[6]input data'!H516 -> 68.59788 | I21: ='[6]input data'!H517 -> 64.752427 | J21: ='[6]input data'!H518 -> 68.097151 | K21: ='[6]input data'!H519 -> 70.836055 | L21: ='[6]input data'!H520 -> 77.967155 | M21: ='[6]input data'!H521 -> 83.922496 | N21: ='[6]input data'!H522 -> 88.187754 | Z21: =AVERAGE(B21:N21) -> 75.200991 | AA21: =MAX(B21:N21) -> 93.447174 | AB21: =MIN(B21:Y21) -> 64.752427
A22: 16 | B22: ='[6]input data'!H546 -> 93.402486 | C22: ='[6]input data'!H547 -> 81.487579 | D22: ='[6]input data'!H548 -> 77.783259 | E22: ='[6]input data'!H549 -> 73.333932 | F22: ='[6]input data'!H550 -> 67.593769 | G22: ='[6]input data'!H551 -> 67.784936 | H22: ='[6]input data'!H552 -> 62.306164 | I22: ='[6]input data'!H553 -> 60.21397 | J22: ='[6]input data'!H554 -> 63.377903 | K22: ='[6]input data'!H555 -> 65.574108 | L22: ='[6]input data'!H556 -> 71.149184 | M22: ='[6]input data'!H557 -> 76.086559 | N22: ='[6]input data'!H558 -> 85.714772 | Z22: =AVERAGE(B22:N22) -> 72.754509 | AA22: =MAX(B22:N22) -> 93.402486 | AB22: =MIN(B22:Y22) -> 60.21397
A23: 17 | B23: ='[6]input data'!H582 -> 88.500299 | C23: ='[6]input data'!H583 -> 82.818962 | D23: ='[6]input data'!H584 -> 70.784128 | E23: ='[6]input data'!H585 -> 66.730466 | F23: ='[6]input data'!H586 -> 63.558266 | G23: ='[6]input data'!H587 -> 62.082173 | H23: ='[6]input data'!H588 -> 63.920308 | I23: ='[6]input data'!H589 -> 60.730696 | J23: ='[6]input data'!H590 -> 63.129839 | K23: ='[6]input data'!H591 -> 67.39965 | L23: ='[6]input data'!H592 -> 74.950053 | M23: ='[6]input data'!H593 -> 81.447158 | N23: ='[6]input data'!H594 -> 84.981827 | Z23: =AVERAGE(B23:N23) -> 71.617987 | AA23: =MAX(B23:N23) -> 88.500299 | AB23: =MIN(B23:Y23) -> 60.730696
A24: 18 | B24: ='[6]input data'!H618 -> 86.904713 | C24: ='[6]input data'!H619 -> 77.831603 | D24: ='[6]input data'!H620 -> 71.58346 | E24: ='[6]input data'!H621 -> 65.505185 | F24: ='[6]input data'!H622 -> 62.306164 | G24: ='[6]input data'!H623 -> 62.380067 | H24: ='[6]input data'!H624 -> 62.073462 | I24: ='[6]input data'!H625 -> 62.887 | J24: ='[6]input data'!H626 -> 65.980311 | K24: ='[6]input data'!H627 -> 70.185833 | L24: ='[6]input data'!H628 -> 91.875379 | M24: ='[6]input data'!H629 -> 91.875379 | N24: ='[6]input data'!H630 -> 91.875379 | Z24: =AVERAGE(B24:N24) -> 74.097226 | AA24: =MAX(B24:N24) -> 91.875379 | AB24: =MIN(B24:Y24) -> 62.073462
A25: 19 | B25: ='[6]input data'!H654 -> 90.241981 | C25: ='[6]input data'!H655 -> 80.103858 | D25: ='[6]input data'!H656 -> 77.50011 | E25: ='[6]input data'!H657 -> 76.387819 | F25: ='[6]input data'!H658 -> 70.0776 | G25: ='[6]input data'!H659 -> 68.475183 | H25: ='[6]input data'!H660 -> 66.244302 | I25: ='[6]input data'!H661 -> 69.970661 | J25: ='[6]input data'!H662 -> 77.642024 | K25: ='[6]input data'!H663 -> 82.818962 | L25: ='[6]input data'!H664 -> 88.605218 | M25: ='[6]input data'!H665 -> 94.08146 | N25: ='[6]input data'!H666 -> 94.881722 | Z25: =AVERAGE(B25:N25) -> 79.771608 | AA25: =MAX(B25:N25) -> 94.881722 | AB25: =MIN(B25:Y25) -> 66.244302
A26: 20 | B26: ='[6]input data'!H690 -> 93.263971 | C26: ='[6]input data'!H691 -> 85.586225 | D26: ='[6]input data'!H692 -> 84.324261 | E26: ='[6]input data'!H693 -> 78.257046 | F26: ='[6]input data'!H694 -> 75.209916 | G26: ='[6]input data'!H695 -> 72.277949 | H26: ='[6]input data'!H696 -> 73.048735 | I26: ='[6]input data'!H697 -> 79.445778 | J26: ='[6]input data'!H698 -> 76.987874 | K26: ='[6]input data'!H699 -> 88.955109 | L26: ='[6]input data'!H700 -> 88.00406 | M26: ='[6]input data'!H701 -> 91.745353 | N26: ='[6]input data'!H702 -> 89.824877 | Z26: =AVERAGE(B26:N26) -> 82.840858 | AA26: =MAX(B26:N26) -> 93.263971 | AB26: =MIN(B26:Y26) -> 72.277949
A27: 21 | B27: ='[6]input data'!H726 -> 95.727062 | C27: ='[6]input data'!H727 -> 90.061668 | D27: ='[6]input data'!H728 -> 82.665948 | E27: ='[6]input data'!H729 -> 78.070462 | F27: ='[6]input data'!H730 -> 74.259747 | G27: ='[6]input data'!H731 -> 70.366824 | H27: ='[6]input data'!H732 -> 69.776989 | I27: ='[6]input data'!H733 -> 71.007147 | J27: ='[6]input data'!H734 -> 76.869444 | K27: ='[6]input data'!H735 -> 80.605071 | L27: ='[6]input data'!H736 -> 84.5944 | M27: ='[6]input data'!H737 -> 84.527935 | N27: ='[6]input data'!H738 -> 88.857799 | Z27: =AVERAGE(B27:N27) -> 80.5685 | AA27: =MAX(B27:N27) -> 95.727062 | AB27: =MIN(B27:Y27) -> 69.776989
A28: 22 | B28: ='[6]input data'!H762 -> 93.200183 | C28: ='[6]input data'!H763 -> 88.47371 | D28: ='[6]input data'!H764 -> 82.781016 | E28: ='[6]input data'!H765 -> 73.516202 | F28: ='[6]input data'!H766 -> 70.306805 | G28: ='[6]input data'!H767 -> 61.022572 | H28: ='[6]input data'!H768 -> 60.958691 | I28: ='[6]input data'!H769 -> 59.192953 | J28: ='[6]input data'!H770 -> 59.901259 | K28: ='[6]input data'!H771 -> 78.833844 | L28: ='[6]input data'!H772 -> 85.388114 | M28: ='[6]input data'!H773 -> 85.320624 | N28: ='[6]input data'!H774 -> 89.968516 | Z28: =AVERAGE(B28:N28) -> 76.066499 | AA28: =MAX(B28:N28) -> 93.200183 | AB28: =MIN(B28:Y28) -> 59.192953
A29: 23 | B29: ='[6]input data'!H798 -> 89.074999 | C29: ='[6]input data'!H799 -> 83.386947 | D29: ='[6]input data'!H800 -> 74.629086 | E29: ='[6]input data'!H801 -> 70.295636 | F29: ='[6]input data'!H802 -> 59.536539 | G29: ='[6]input data'!H803 -> 54.040371 | H29: ='[6]input data'!H804 -> 58.120518 | I29: ='[6]input data'!H805 -> 53.064296 | J29: ='[6]input data'!H806 -> 53.980167 | K29: ='[6]input data'!H807 -> 59.350053 | L29: ='[6]input data'!H808 -> 79.18898 | M29: ='[6]input data'!H809 -> 83.115365 | N29: ='[6]input data'!H810 -> 85.113759 | Z29: =AVERAGE(B29:N29) -> 69.453594 | AA29: =MAX(B29:N29) -> 89.074999 | AB29: =MIN(B29:Y29) -> 53.064296
A30: 24 | B30: ='[6]input data'!H834 -> 88.393064 | C30: ='[6]input data'!H835 -> 80.538518 | D30: ='[6]input data'!H836 -> 69.561734 | E30: ='[6]input data'!H837 -> 62.786899 | F30: ='[6]input data'!H838 -> 57.531256 | G30: ='[6]input data'!H839 -> 52.688087 | H30: ='[6]input data'!H840 -> 51.495293 | I30: ='[6]input data'!H841 -> 52.038439 | J30: ='[6]input data'!H842 -> 59.236831 | K30: ='[6]input data'!H843 -> 69.253652 | L30: ='[6]input data'!H844 -> 79.275468 | M30: ='[6]input data'!H845 -> 88.31485 | N30: ='[6]input data'!H846 -> 88.083626 | Z30: =AVERAGE(B30:N30) -> 69.169055 | AA30: =MAX(B30:N30) -> 88.393064 | AB30: =MIN(B30:Y30) -> 51.495293
A31: 25 | B31: ='[6]input data'!H870 -> 95.786752 | C31: ='[6]input data'!H871 -> 91.059086 | D31: ='[6]input data'!H872 -> 85.242912 | E31: ='[6]input data'!H873 -> 76.437114 | F31: ='[6]input data'!H874 -> 71.194306 | G31: ='[6]input data'!H875 -> 70.426534 | H31: ='[6]input data'!H876 -> 64.46712 | I31: ='[6]input data'!H877 -> 68.351235 | J31: ='[6]input data'!H878 -> 79.571225 | K31: ='[6]input data'!H879 -> 82.106146 | L31: ='[6]input data'!H880 -> 88.393064 | M31: ='[6]input data'!H881 -> 92.327521 | N31: ='[6]input data'!H882 -> 93.216262 | Z31: =AVERAGE(B31:N31) -> 81.429175 | AA31: =MAX(B31:N31) -> 95.786752 | AB31: =MIN(B31:Y31) -> 64.46712
A32: 26 | B32: ='[6]input data'!H906 -> 96.559175 | C32: ='[6]input data'!H907 -> 88.656828 | D32: ='[6]input data'!H908 -> 81.487579 | E32: ='[6]input data'!H909 -> 75.436041 | F32: ='[6]input data'!H910 -> 77.595485 | G32: ='[6]input data'!H911 -> 85.902496 | H32: ='[6]input data'!H912 -> 90.152804 | I32: ='[6]input data'!H913 -> 91.570733 | J32: ='[6]input data'!H914 -> 97.344952 | K32: ='[6]input data'!H915 -> 98.235474 | L32: ='[6]input data'!H916 -> 98.231146 | M32: ='[6]input data'!H917 -> 98.20466 | N32: ='[6]input data'!H918 -> 98.209137 | Z32: =AVERAGE(B32:N32) -> 90.583578 | AA32: =MAX(B32:N32) -> 98.235474 | AB32: =MIN(B32:Y32) -> 75.436041
A33: 27 | B33: ='[6]input data'!H942 -> 87.998499 | C33: ='[6]input data'!H943 -> 82.430152 | D33: ='[6]input data'!H944 -> 81.487579 | E33: ='[6]input data'!H945 -> 77.50011 | F33: ='[6]input data'!H946 -> 72.262296 | G33: ='[6]input data'!H947 -> 68.878309 | H33: ='[6]input data'!H948 -> 71.502977 | I33: ='[6]input data'!H949 -> 70.063603 | J33: ='[6]input data'!H950 -> 70.063603 | K33: ='[6]input data'!H951 -> 73.627426 | L33: ='[6]input data'!H952 -> 75.984005 | M33: ='[6]input data'!H953 -> 77.007783 | N33: ='[6]input data'!H954 -> 80.987935 | Z33: =AVERAGE(B33:N33) -> 76.138021 | AA33: =MAX(B33:N33) -> 87.998499 | AB33: =MIN(B33:Y33) -> 68.878309
A34: 28 | B34: ='[6]input data'!H978 -> 89.873288 | C34: ='[6]input data'!H979 -> 83.083191 | D34: ='[6]input data'!H980 -> 73.403802 | E34: ='[6]input data'!H981 -> 66.42899 | F34: ='[6]input data'!H982 -> 64.253727 | G34: ='[6]input data'!H983 -> 56.868629 | H34: ='[6]input data'!H984 -> 54.62526 | I34: ='[6]input data'!H985 -> 64.549111 | J34: ='[6]input data'!H986 -> 65.225911 | K34: ='[6]input data'!H987 -> 67.580322 | L34: ='[6]input data'!H988 -> 76.437114 | M34: ='[6]input data'!H989 -> 79.726075 | N34: ='[6]input data'!H990 -> 77.783063 | Z34: =AVERAGE(B34:N34) -> 70.756806 | AA34: =MAX(B34:N34) -> 89.873288 | AB34: =MIN(B34:Y34) -> 54.62526
A35: 29 | B35: ='[6]input data'!H1014 -> 86.046719 | C35: ='[6]input data'!H1015 -> 79.751571 | D35: ='[6]input data'!H1016 -> 77.92791 | E35: ='[6]input data'!H1017 -> 71.149184 | F35: ='[6]input data'!H1018 -> 67.71214 | G35: ='[6]input data'!H1019 -> 62.618462 | H35: ='[6]input data'!H1020 -> 55.890144 | I35: ='[6]input data'!H1021 -> 64.815566 | J35: ='[6]input data'!H1022 -> 68.035786 | K35: ='[6]input data'!H1023 -> 78.7427 | L35: ='[6]input data'!H1024 -> 81.15808 | M35: ='[6]input data'!H1025 -> 83.160372 | N35: ='[6]input data'!H1026 -> 86.143233 | Z35: =AVERAGE(B35:N35) -> 74.088605 | AA35: =MAX(B35:N35) -> 86.143233 | AB35: =MIN(B35:Y35) -> 55.890144
A36: 30 | B36: ='[6]input data'!H1050 -> 89.022905 | C36: ='[6]input data'!H1051 -> 82.349831 | D36: ='[6]input data'!H1052 -> 72.9421 | E36: ='[6]input data'!H1053 -> 67.447127 | F36: ='[6]input data'!H1054 -> 60.945439 | G36: ='[6]input data'!H1055 -> 58.188289 | H36: ='[6]input data'!H1056 -> 42.272913 | I36: ='[6]input data'!H1057 -> 42.700611 | J36: ='[6]input data'!H1058 -> 71.845967 | K36: ='[6]input data'!H1059 -> 77.783259 | L36: ='[6]input data'!H1060 -> 77.306313 | M36: ='[6]input data'!H1061 -> 85.778016 | N36: ='[6]input data'!H1062 -> 91.570733 | Z36: =AVERAGE(B36:N36) -> 70.781039 | AA36: =MAX(B36:N36) -> 91.570733 | AB36: =MIN(B36:Y36) -> 42.272913
A37: 31 | B37: ='[6]input data'!H1086 -> 88.17137 | C37: ='[6]input data'!H1087 -> 80.725678 | D37: ='[6]input data'!H1088 -> 76.490431 | E37: ='[6]input data'!H1089 -> 71.149184 | F37: ='[6]input data'!H1090 -> 67.580322 | G37: ='[6]input data'!H1091 -> 65.998049 | H37: ='[6]input data'!H1092 -> 64.46712 | I37: ='[6]input data'!H1093 -> 72.939843 | J37: ='[6]input data'!H1094 -> 76.486153 | K37: ='[6]input data'!H1095 -> 76.288451 | L37: ='[6]input data'!H1096 -> 85.840588 | M37: ='[6]input data'!H1097 -> 90.285852 | N37: ='[6]input data'!H1098 -> 94.99967 | Z37: =AVERAGE(B37:N37) -> 77.801747 | AA37: =MAX(B37:N37) -> 94.99967 | AB37: =MIN(B37:Y37) -> 64.46712
A38: Max | B38: =MAX(B7:B37) -> 96.559175 | C38: =MAX(C7:C37) -> 91.929622 | D38: =MAX(D7:D37) -> 85.242912 | E38: =MAX(E7:E37) -> 79.529624 | F38: =MAX(F7:F37) -> 77.595485 | G38: =MAX(G7:G37) -> 85.902496 | H38: =MAX(H7:H37) -> 90.152804 | I38: =MAX(I7:I37) -> 96.623276 | ... N38: =MAX(N7:N37) -> 98.209137 | Z38: =MAX(Z7:Z37) -> 90.583578 | AA38: =MAX(AA7:AA37) -> 98.235474 | AB38: =MAX(AB7:AB37) -> 75.436041
A39: Min | B39: =MIN(B7:B37) -> 76.742439 | C39: =MIN(C7:C37) -> 75.106784 | D39: =MIN(D7:D37) -> 68.357245 | E39: =MIN(E7:E37) -> 62.006739 | F39: =MIN(F7:F37) -> 57.36275 | G39: =MIN(G7:G37) -> 52.688087 | H39: =MIN(H7:H37) -> 42.272913 | I39: =MIN(I7:I37) -> 42.700611 | ... N39: =MIN(N7:N37) -> 77.783063 | Z39: =MIN(Z8:Z38) -> 68.581789 | AA39: =MIN(AA8:AA38) -> 84.184813 | AB39: =MIN(AB8:AB38) -> 42.272913
A40: X | B40: =AVERAGE(B7:B37) -> 90.084913 | C40: =AVERAGE(C7:C37) -> 82.812133 | D40: =AVERAGE(D7:D37) -> 76.5908 | E40: =AVERAGE(E7:E37) -> 71.452852 | F40: =AVERAGE(F7:F37) -> 67.198998 | G40: =AVERAGE(G7:G37) -> 65.254879 | H40: =AVERAGE(H7:H37) -> 63.804754 | I40: =AVERAGE(I7:I37) -> 66.578918 | ... N40: =AVERAGE(N7:N37) -> 89.128082 | Z40: =AVERAGE(Z9:Z39) -> 76.573909 | AA40: =AVERAGE(AA9:AA39) -> 92.138055 | AB40: =AVERAGE(AB9:AB39) -> 61.491693
A43: Keterangan:
B44: : Tidak ada pengamatan
...

Sheet JUNI
R2: DATA KELEMBABAN
R3: Bulan : | T3: ='[7]1'!AA1 -> JUNI | V3: =JANUARI!V3 -> 2022
A5: JAM | B5: 00.00 | C5: 01.00 | D5: 02.00 | E5: 03.00 | F5: 04.00 | G5: 05.00 | H5: 06.00 | I5: 07.00 | J5: 08.00 | K5: 09.00 | L5: 10.00 | M5: 11.00 | N5: 12.00 | O5: 13.00 | P5: 14.00 | Q5: 15.00 | R5: 16.00 | S5: 17.00 | T5: 18.00 | U5: 19.00 | V5: 20.00 | W5: 21.00 | X5: 22.00 | Y5: 23.00 | Z5: rata2 | AA5: Max | AB5: Min
A6: TGL | B6: 1 | C6: 2 | D6: 3 | E6: 4 | F6: 5 | G6: 6 | H6: 7 | I6: 8 | J6: 9 | K6: 10 | L6: 11 | M6: 12 | N6: 13 | O6: 14 | P6: 15 | Q6: 16 | R6: 17 | S6: 18 | T6: 19 | U6: 20 | V6: 21 | W6: 22 | X6: 23 | Y6: 24 | Z6: 25 | AA6: 26 | AB6: 27
A7: 1 | B7: 96.526048 | C7: 94.08146 | D7: 82.588198 | E7: 88.00406 | F7: 77.007783 | G7: 75.106784 | H7: 68.621521 | I7: 68.878309 | J7: 70.603005 | K7: 76.043836 | L7: 76.987874 | M7: 85.178678 | N7: 84.184813 | Z7: =AVERAGE(B7:N7) -> 80.293259 | AA7: =MAX(B7:N7) -> 96.526048 | AB7: =MIN(B7:Y7) -> 68.621521
A8: 2 | B8: 91.490304 | C8: 77.007783 | D8: 69.497506 | E8: 68.556484 | F8: 69.342913 | G8: 65.574108 | H8: 71.73281 | I8: 71.845967 | J8: 75.209916 | K8: 76.288451 | L8: 78.833844 | M8: 82.894249 | N8: 85.714772 | Z8: =AVERAGE(B8:N8) -> 75.69147 | AA8: =MAX(B8:N8) -> 91.490304 | AB8: =MIN(B8:Y8) -> 65.574108
A9: 3 | B9: 90.894492 | C9: 78.36827 | D9: 75.722805 | E9: 70.659857 | F9: 74.683289 | G9: 74.790838 | H9: 72.086168 | I9: 72.378181 | J9: 76.387819 | K9: 73.516202 | L9: 80.017192 | M9: 82.742866 | N9: 85.586225 | Z9: =AVERAGE(B9:N9) -> 77.525708 | AA9: =MAX(B9:N9) -> 90.894492 | AB9: =MIN(B9:Y9) -> 70.659857
A10: 4 | B10: 88.17137 | C10: 80.320208 | D10: 78.463383 | E10: 76.188036 | F10: 70.357755 | G10: 67.965836 | H10: 67.513898 | I10: 72.108362 | J10: 71.993833 | K10: 76.238376 | L10: 81.365667 | M10: 90.285852 | N10: 92.624836 | Z10: =AVERAGE(B10:N10) -> 77.969032 | AA10: =MAX(B10:N10) -> 92.624836 | AB10: =MIN(B10:Y10) -> 67.513898
A11: 5 | B11: 94.953264 | C11: 90.977681 | D11: 84.324261 | E11: 78.164247 | F11: 73.279039 | G11: 68.421304 | H11: 72.277949 | I11: 67.8426 | J11: 73.954201 | K11: 86.782451 | L11: 82.742866 | M11: 90.015348 | N11: 91.570733 | Z11: =AVERAGE(B11:N11) -> 81.17738 | AA11: =MAX(B11:N11) -> 94.953264 | AB11: =MIN(B11:Y11) -> 67.8426
A12: 6 | B12: 89.921165 | C12: 84.042334 | D12: 76.086559 | E12: 72.262296 | F12: 66.699167 | G12: 70.185833 | H12: 72.60635 | I12: 87.083169 | J12: 83.822741 | K12: 85.320624 | L12: 86.720303 | M12: 91.449415 | N12: 94.807772 | Z12: =AVERAGE(B12:N12) -> 81.615979 | AA12: =MAX(B12:N12) -> 94.807772 | AB12: =MIN(B12:Y12) -> 66.699167
A13: 7 | B13: 94.75708 | C13: 83.785438 | D13: 82.070418 | E13: 71.268343 | F13: 64.736797 | G13: 60.025341 | H13: 57.197262 | I13: 57.698044 | J13: 56.773205 | K13: 60.789979 | L13: 80.061878 | M13: 84.5944 | N13: 85.902496 | Z13: =AVERAGE(B13:N13) -> 72.281591 | AA13: =MAX(B13:N13) -> 94.75708 | AB13: =MIN(B13:Y13) -> 56.773205
A14: 8 | B14: 90.061668 | C14: 79.929598 | D14: 74.150907 | E14: 67.71214 | F14: 63.232427 | G14: 60.520376 | H14: 60.671269 | I14: 75.611927 | J14: 82.068982 | K14: 93.938616 | L14: 95.612349 | M14: 95.633733 | N14: 98.239777 | Z14: =AVERAGE(B14:N14) -> 79.798751 | AA14: =MAX(B14:N14) -> 98.239777 | AB14: =MIN(B14:Y14) -> 60.520376
A15: 9 | B15: 95.654879 | C15: 91.688099 | D15: 84.254911 | E15: 78.650584 | F15: 74.790838 | G15: 72.262296 | H15: 71.149184 | I15: 71.618485 | J15: 71.618485 | K15: 76.583469 | L15: 84.725253 | M15: 90.456707 | N15: 91.875379 | Z15: =AVERAGE(B15:N15) -> 81.179121 | AA15: =MAX(B15:N15) -> 95.654879 | AB15: =MIN(B15:Y15) -> 71.149184
A16: 10 | B16: 93.101815 | C16: 91.688099 | D16: 78.36827 | E16: 70.722157 | F16: 66.291788 | G16: 66.42899 | H16: 67.202518 | I16: 66.269276 | J16: 67.029162 | K16: 71.268343 | L16: 77.595485 | M16: 83.783827 | N16: 87.477795 | Z16: =AVERAGE(B16:N16) -> 75.940579 | AA16: =MAX(B16:N16) -> 93.101815 | AB16: =MIN(B16:Y16) -> 66.269276
A17: 11 | B17: 87.615231 | C17: 74.6765 | D17: 76.188036 | E17: 67.580322 | F17: 66.201991 | G17: 67.094154 | H17: 60.958691 | I17: 64.746586 | J17: 81.880238 | K17: 84.113958 | L17: 93.387428 | M17: 93.295342 | N17: 93.295342 | Z17: =AVERAGE(B17:N17) -> 77.771832 | AA17: =MAX(B17:N17) -> 93.387428 | AB17: =MIN(B17:Y17) -> 60.958691
A18: 12 | B18: 95.696469 | C18: 86.238178 | D18: 76.283935 | E18: 69.815294 | F18: 67.002309 | G18: 64.46712 | H18: 58.548278 | I18: 69.715936 | J18: 82.603584 | K18: 80.232144 | L18: 82.968738 | M18: 86.632266 | N18: 89.588847 | Z18: =AVERAGE(B18:N18) -> 77.676392 | AA18: =MAX(B18:N18) -> 95.696469 | AB18: =MIN(B18:Y18) -> 58.548278
... A36: 30 | B36: 86.740997 | C36: 82.725205 | D36: 74.620033 | E36: 68.288902 | F36: 65.065538 | G36: 66.522824 | H36: 53.908526 | I36: 55.833676 | J36: 59.256212 | K36: 62.170825 | L36: 62.822016 | M36: 74.013398 | N36: 80.636328 | Z36: =AVERAGE(B36:N36) -> 68.661883 | AA36: =MAX(B36:N36) -> 86.740997 | AB36: =MIN(B36:Y36) -> 53.908526
A37: Max | B37: =MAX(B7:B36) -> 96.526048 | C37: =MAX(C7:C36) -> 94.08146 | D37: =MAX(D7:D36) -> 84.324261 | E37: =MAX(E7:E36) -> 88.00406 | F37: =MAX(F7:F36) -> 79.811342 | G37: =MAX(G7:G36) -> 84.113958 | H37: =MAX(H7:H36) -> 98.213589 | I37: =MAX(I7:I36) -> 93.909081 | ... N37: =MAX(N7:N36) -> 98.239777 | Z37: =MAX(Z7:Z36) -> 90.678826 | AA37: =MAX(AA7:AA36) -> 100 | AB37: =MAX(AB7:AB36) -> 77.595485
A38: Min | B38: =MIN(B7:B36) -> 85.113652 | C38: =MIN(C7:C36) -> 72.43457 | D38: =MIN(D7:D36) -> 67.108061 | E38: =MIN(E7:E36) -> 61.514997 | F38: =MIN(F7:F36) -> 58.215856 | G38: =MIN(G7:G36) -> 55.764397 | H38: =MIN(H7:H36) -> 52.921845 | I38: =MIN(I7:I36) -> 54.040371 | ... N38: =MIN(N7:N36) -> 73.661877 | Z38: =MIN(Z8:Z37) -> 66.378079 | AA38: =MIN(AA8:AA37) -> 85.113652 | AB38: =MIN(AB8:AB37) -> 52.921845
A39: X | B39: =AVERAGE(B7:B36) -> 91.265501 | C39: =AVERAGE(C7:C36) -> 84.439591 | D39: =AVERAGE(D7:D36) -> 77.677179 | E39: =AVERAGE(E7:E36) -> 71.398247 | F39: =AVERAGE(F7:F36) -> 68.411394 | G39: =AVERAGE(G7:G36) -> 67.170535 | H39: =AVERAGE(H7:H36) -> 66.155294 | I39: =AVERAGE(I7:I36) -> 68.418286 | ... N39: =AVERAGE(N7:N36) -> 87.475582 | Z39: =AVERAGE(Z9:Z38) -> 76.785488 | AA39: =AVERAGE(AA9:AA38) -> 92.465798 | AB39: =AVERAGE(AB9:AB38) -> 63.819001
A40: Keterangan:
B41: : Tidak ada pengamatan
Y42: Yogyakarta, 05 Juli 2021
Y43: =[1]COVER!X4 -> PEMBUAT LAPORAN,
Y46: Yudha Tintana Marganiswati
Y47: NIP. 198310292004122001

Sheet JULI
R2: DATA KELEMBABAN
R3: Bulan : | T3: ='[8]1'!AA1 -> JULI | V3: =JANUARI!V3 -> 2022
A5: JAM | B5: 00.00 | C5: 01.00 | D5: 02.00 | E5: 03.00 | F5: 04.00 | G5: 05.00 | H5: 06.00 | I5: 07.00 | J5: 08.00 | K5: 09.00 | L5: 10.00 | M5: 11.00 | N5: 12.00 | O5: 13.00 | P5: 14.00 | Q5: 15.00 | R5: 16.00 | S5: 17.00 | T5: 18.00 | U5: 19.00 | V5: 20.00 | W5: 21.00 | X5: 22.00 | Y5: 23.00 | Z5: rata2 | AA5: Max | AB5: Min
A6: TGL | B6: 1 | C6: 2 | D6: 3 | E6: 4 | F6: 5 | G6: 6 | H6: 7 | I6: 8 | J6: 9 | K6: 10 | L6: 11 | M6: 12 | N6: 13 | O6: 14 | P6: 15 | Q6: 16 | R6: 17 | S6: 18 | T6: 19 | U6: 20 | V6: 21 | W6: 22 | X6: 23 | Y6: 24 | Z6: 25 | AA6: 26 | AB6: 27
A7: 1 | B7: 85.881802 | C7: 79.434091 | D7: 74.391078 | E7: 65.952794 | F7: 62.327271 | G7: 57.359403 | H7: 57.614864 | I7: 57.876459 | J7: 61.38903 | K7: 62.635286 | L7: 68.091531 | M7: 69.952201 | N7: 75.122905 | Z7: =AVERAGE(B7:N7) -> 67.54067 | AA7: =MAX(B7:N7) -> 85.881802 | AB7: =MIN(B7:Y7) -> 57.359403
A8: 2 | B8: 82.782267 | C8: 85.113652 | D8: 78.174946 | E8: 69.302774 | F8: 64.86857 | G8: 62.786899 | H8: 67.8426 | I8: 72.662654 | J8: 85.015075 | K8: 85.902496 | L8: 82.818962 | M8: 84.113958 | N8: 85.586225 | Z8: =AVERAGE(B8:N8) -> 77.459314 | AA8: =MAX(B8:N8) -> 85.902496 | AB8: =MIN(B8:Y8) -> 62.786899
A9: 3 | B9: 93.295342 | C9: 86.362387 | D9: 79.286008 | E9: 73.627426 | F9: 70.843197 | G9: 65.980311 | H9: 61.551605 | I9: 66.244302 | J9: 83.187526 | K9: 88.955109 | L9: 88.808362 | M9: 90.329253 | N9: 91.801681 | Z9: =AVERAGE(B9:N9) -> 80.020962 | AA9: =MAX(B9:N9) -> 93.295342 | AB9: =MIN(B9:Y9) -> 61.551605
A10: 4 | B10: 94.08146 | C10: 87.785499 | D10: 82.968738 | E10: 79.639909 | F10: 67.334277 | G10: 66.534998 | H10: 63.521897 | I10: 59.93414 | J10: 61.033921 | K10: 53.625351 | L10: 74.374395 | M10: 86.945074 | N10: 91.23598 | Z10: =AVERAGE(B10:N10) -> 74.539665 | AA10: =MAX(B10:N10) -> 94.08146 | AB10: =MIN(B10:Y10) -> 53.625351
A11: 5 | B11: 89.10083 | C11: 84.042334 | D11: 76.137432 | E11: 67.8426 | F11: 65.710897 | G11: 64.746586 | H11: 64.952479 | I11: 72.341154 | J11: 70.485939 | K11: 73.550684 | L11: 81.159545 | M11: 86.719384 | N11: 88.161929 | Z11: =AVERAGE(B11:N11) -> 75.765523 | AA11: =MAX(B11:N11) -> 89.10083 | AB11: =MIN(B11:Y11) -> 64.746586
A12: 6 | B12: 89.873288 | C12: 86.300619 | D12: 77.207863 | E12: 74.844189 | F12: 78.7427 | G12: 69.940096 | H12: 69.342913 | I12: 67.580322 | J12: 84.9484 | K12: 81.487579 | L12: 82.818962 | M12: 84.184813 | N12: 89.375791 | Z12: =AVERAGE(B12:N12) -> 79.742118 | AA12: =MAX(B12:N12) -> 89.873288 | AB12: =MIN(B12:Y12) -> 67.580322
A13: 7 | B13: 88.05677 | C13: 84.532859 | D13: 72.996352 | E13: 62.011865 | F13: 64.125147 | G13: 64.155824 | H13: 63.74275 | I13: 60.363303 | J13: 59.117323 | K13: 60.197894 | L13: 61.196537 | M13: 68.771704 | N13: 73.978177 | Z13: =AVERAGE(B13:N13) -> 67.942039 | AA13: =MAX(B13:N13) -> 88.05677 | AB13: =MIN(B13:Y13) -> 59.117323
A14: 8 | B14: 86.265361 | C14: 80.315719 | D14: 72.624926 | E14: 63.260336 | F14: 64.246104 | G14: 59.34397 | H14: 87.793544 | I14: 56.814419 | J14: 59.900556 | K14: 64.369899 | L14: 68.066383 | M14: 71.82761 | N14: 73.174905 | Z14: =AVERAGE(B14:N14) -> 69.846441 | AA14: =MAX(B14:N14) -> 87.793544 | AB14: =MIN(B14:Y14) -> 56.814419
A15: 9 | B15: 80.935634 | C15: 75.711674 | D15: 67.62664 | E15: 62.257726 | F15: 65.140772 | G15: 68.768032 | H15: 72.823564 | I15: 71.415854 | J15: 72.582631 | K15: 76.594483 | L15: 80.725678 | M15: 85.043124 | N15: 86.593927 | Z15: =AVERAGE(B15:N15) -> 74.324595 | AA15: =MAX(B15:N15) -> 86.593927 | AB15: =MIN(B15:Y15) -> 62.257726
A16: 10 | B16: 84.050213 | C16: 80.268893 | D16: 72.624926 | E16: 68.491929 | F16: 65.806464 | G16: 63.971678 | H16: 63.135433 | I16: 65.012624 | J16: 63.593304 | K16: 64.575896 | L16: 65.583842 | M16: 70.279028 | N16: 78.174946 | Z16: =AVERAGE(B16:N16) -> 69.659167 | AA16: =MAX(B16:N16) -> 84.050213 | AB16: =MIN(B16:Y16) -> 63.135433
A17: 11 | B17: 91.237959 | C17: 82.019604 | D17: 78.076706 | E17: 67.818016 | F17: 61.309994 | G17: 57.362744 | H17: 65.36627 | I17: 66.564776 | J17: 88.553044 | K17: 99.100725 | L17: 96.526048 | M17: 98.256754 | N17: 96.575466 | Z17: =AVERAGE(B17:N17) -> 80.67447 | AA17: =MAX(B17:N17) -> 99.100725 | AB17: =MIN(B17:Y17) -> 57.362744
A18: 12 | B18: 96.51765 | C18: 88.605218 | D18: 82.665948 | E18: 77.50011 | F18: 65.58055 | G18: 62.165255 | H18: 59.8641 | I18: 63.664428 | J18: 70.843197 | K18: 75.795204 | L18: 82.968738 | M18: 88.857799 | N18: 90.329253 | Z18: =AVERAGE(B18:N18) -> 77.335188 | AA18: =MAX(B18:N18) -> 96.51765 | AB18: =MIN(B18:Y18) -> 59.8641
... A37: 31 | B37: 90.873593 | C37: 83.200466 | D37: 76.916484 | E37: 65.732711 | F37: 65.583842 | G37: 64.155824 | H37: 64.723001 | I37: 63.890644 | J37: 65.58055 | K37: 68.827041 | L37: 72.9421 | M37: 73.661877 | N37: 80.725678 | Z37: =AVERAGE(B37:N37) -> 72.062601 | AA37: =MAX(B37:N37) -> 90.873593 | AB37: =MIN(B37:Y37) -> 63.890644
A38: Max | B38: =MAX(B7:B37) -> 96.51765 | C38: =MAX(C7:C37) -> 94.08146 | D38: =MAX(D7:D37) -> 91.649406 | E38: =MAX(E7:E37) -> 86.143233 | F38: =MAX(F7:F37) -> 82.349831 | G38: =MAX(G7:G37) -> 77.977393 | H38: =MAX(H7:H37) -> 87.793544 | I38: =MAX(I7:I37) -> 77.108358 | ... N38: =MAX(N7:N37) -> 96.575466 | Z38: =MAX(Z7:Z37) -> 83.795675 | AA38: =MAX(AA7:AA37) -> 99.100725 | AB38: =MAX(AB7:AB37) -> 75.009938
